Workbook

Sheet Plan
A1: RGBKart Marketplace – Project Plan
A2: How to use: update Status, Start date, End date and Remarks (cream-coloured cells). Days and the Summary tab update themselves. Phase 0 rows show the expected format.
A4: Phase | B4: Phase name | C4: ID | D4: Sub-phase | E4: What gets built | F4: Status | G4: Start date | H4: End date | I4: Days | J4: Remarks
A5: 0 | B5: Foundation (accounts & admin) | C5: 0.1 | D5: Supabase project & keys | E5: Project created; project URL and publishable key connected to the app | F5: Done | G5: 46317 | H5: 46317 | I5: =IF(AND(G5<>"",H5<>""),H5-G5+1,"") | J5: Done 22 Oct 2026
A6: 0 | B6: Foundation (accounts & admin) | C6: 0.2 | D6: Email sign-up & sign-in | E6: Create account, sign in, sign out with email + password | F6: Done | G6: 46317 | H6: 46317 | I6: =IF(AND(G6<>"",H6<>""),H6-G6+1,"")
A7: 0 | B7: Foundation (accounts & admin) | C7: 0.3 | D7: Forgot password | E7: Reset link by email and 'Set a new password' screen | F7: Done | G7: 46317 | H7: 46317 | I7: =IF(AND(G7<>"",H7<>""),H7-G7+1,"") | J7: Works only when the site runs from a web address (localhost or domain)
A8: 0 | B8: Foundation (accounts & admin) | C8: 0.4 | D8: Google & Facebook sign-in | E8: Buttons built; provider apps must be configured | F8: In progress | G8: 46317 | I8: =IF(AND(G8<>"",H8<>""),H8-G8+1,"") | J8: Code done. To do: Google Cloud OAuth client, Meta app, enable both in Supabase, set Site URL + Redirect URLs
A9: 0 | B9: Foundation (accounts & admin) | C9: 0.5 | D9: Customer & Seller sign-up | E9: Separate forms; sellers start as 'Pending approval' | F9: Done | G9: 46317 | H9: 46317 | I9: =IF(AND(G9<>"",H9<>""),H9-G9+1,"") | J9: profiles.sql
A10: 0 | B10: Foundation (accounts & admin) | C10: 0.6 | D10: Admin panel & staff roles | E10: admin.html: Master Admin, Co-admin, Editor; invite by email; approve sellers | F10: Done | G10: 46317 | H10: 46317 | I10: =IF(AND(G10<>"",H10<>""),H10-G10+1,"") | J10: admin.sql; permissions tested on a test database
A11: 0 | B11: Foundation (accounts & admin) | C11: 0.7 | D11: Install & live test | E11: Run setup.sql, profiles.sql, admin.sql; make yourself Master Admin; test every sign-in flow | F11: Done | G11: 46317 | H11: 46317 | I11: =IF(AND(G11<>"",H11<>""),H11-G11+1,"") | J11: All 3 SQL files run OK; hkmanik@gmail.com is Master Admin (22 Oct). To do: URL Configuration, open admin.html, test sign-in flows
A12: 1 | B12: Catalog & Seller Products | C12: 1.1 | D12: Admin sidebar layout | E12: Left sidebar menu grouped by Catalog, People, Storefront, Money, Settings; folds to a menu button on phones | F12: Done | G12: 46317 | H12: 46317 | I12: =IF(AND(G12<>"",H12<>""),H12-G12+1,"") | J12: Built 22 Oct in admin.html. Test after running catalog.sql
A13: 1 | B13: Catalog & Seller Products | C13: 1.2 | D13: Categories & sub-categories | E13: One tree (e.g. Electronics › Mobile › Smartphones) with icon, sort order, on/off | F13: Done | G13: 46317 | H13: 46317 | I13: =IF(AND(G13<>"",H13<>""),H13-G13+1,"") | J13: Built 22 Oct. catalog_seed.sql adds 20 categories + 100 sub-categories (editable)
A14: 1 | B14: Catalog & Seller Products | C14: 1.3 | D14: Attributes | E14: Create attributes (Colour, Size, RAM…) and attach them to categories | F14: Done | G14: 46317 | H14: 46317 | I14: =IF(AND(G14<>"",H14<>""),H14-G14+1,"") | J14: Built 22 Oct. catalog_seed.sql adds 136 dropdown attributes, 1,315 choices, linked to categories
A15: 1 | B15: Catalog & Seller Products | C15: 1.4 | D15: Product database & image storage | E15: Products table, Supabase Storage bucket for photos, security rules | F15: Done | G15: 46317 | H15: 46317 | I15: =IF(AND(G15<>"",H15<>""),H15-G15+1,"") | J15: Built 22 Oct (products.sql): product tables, review flow, photo bucket. Tested; installed in Supabase 22 Oct
A16: 1 | B16: Catalog & Seller Products | C16: 1.5 | D16: Seller: add & edit products | E16: Approved sellers add title, price (৳), photos, description, category, attribute values | F16: Done | G16: 46317 | H16: 46317 | I16: =IF(AND(G16<>"",H16<>""),H16-G16+1,"") | J16: Built 22 Oct: seller.html + products_v2.sql + product_options.sql. New / Pre-owned, Free listing / Featured, Main + 7 gallery photos, pricing, stock, shipping, linked products; Downloadable, Service, Gift card, Pre-order, Wholesale price, COD on/off
A17: 1 | B17: Catalog & Seller Products | C17: 1.6 | D17: Variants & stock | E17: Size/colour options with their own price and stock count | F17: Done | G17: 46317 | H17: 46317 | I17: =IF(AND(G17<>"",H17<>""),H17-G17+1,"") | J17: Built with 1.5: variations (e.g. Colour × Storage) with own price, sale, stock, SKU, photo
A18: 1 | B18: Catalog & Seller Products | C18: 1.7 | D18: Product approval | E18: Editor / Co-admin review new products before they go live | F18: Done | G18: 46317 | H18: 46317 | I18: =IF(AND(G18<>"",H18<>""),H18-G18+1,"") | J18: Built 22 Oct: admin Products page (approve / reject with reason / take down). Also: one-time sellers via sell.html (no account), simpler Add product form. 22 Oct: one-time sellers choose Free (buyers message only, phone hidden) or Featured (call, WhatsApp, email, message)
A19: 1 | B19: Catalog & Seller Products | C19: 1.8 | D19: Seller shop page | E19: Public page per shop: logo, banner, products | F19: Done | G19: 46317 | H19: 46317 | I19: =IF(AND(G19<>"",H19<>""),H19-G19+1,"") | J19: Shop settings built 22 Oct (shop_settings.sql): logo, banner, web address, contact, social links, vacation mode, payout details. Public shop page still to build · 23 Oct: store.html?s=<shop> with banner, logo, contact, about, search, category filter, sort and pages; linked from product, cart and orders
A20: 2 | B20: Customer Shopping | C20: 2.1 | D20: Home page | E20: Banners, featured categories, new and popular products | F20: In progress | G20: 46317 | I20: =IF(AND(G20<>"",H20<>""),H20-G20+1,"") | J20: Updated 22 Oct: 6×2 category cards, All categories page (categories.html), admin-managed product sections (Featured, Deals of the Day, New arrivals…), New/Pre-owned/Sale labels, heart, cart icon with count. Banners editable later (5.9) · 23 Oct: Top shops sliding row, new section types (with options, brand new, negotiable), category pictures
A21: 2 | B21: Customer Shopping | C21: 2.2 | D21: Product listing & filters | E21: Browse by category; filter by price, brand, rating; sort | F21: In progress | G21: 46317 | I21: =IF(AND(G21<>"",H21<>""),H21-G21+1,"") | J21: Built 22 Oct (browse.html): left sidebar with expandable categories, filters (condition, price, district, featured, free delivery), sort, show more · 23 Oct: page numbers with Previous / Next (24 per page), fixed header and menu, coloured sub-category buttons, picture icons in the sidebar
A22: 2 | B22: Customer Shopping | C22: 2.3 | D22: Search | E22: Search by product name, shop, category | F22: In progress | G22: 46317 | I22: =IF(AND(G22<>"",H22<>""),H22-G22+1,"") | J22: Built 22 Oct: search by name, description and tags; matching categories suggested. Cart page (cart.html) added
A23: 2 | B23: Customer Shopping | C23: 2.4 | D23: Product detail page | E23: Photos, variants, stock, seller info, delivery estimate | F23: In progress | G23: 46317 | I23: =IF(AND(G23<>"",H23<>""),H23-G23+1,"") | J23: Built 22 Oct (product.html): gallery, variations, price/sale, stock, Contact seller (Call/WhatsApp), Add to cart, Buy now. Cart saved on device until checkout (3.2)
A24: 2 | B24: Customer Shopping | C24: 2.5 | D24: Wishlist | E24: Customers save products for later | F24: Done | G24: 46317 | H24: 46318 | I24: =IF(AND(G24<>"",H24<>""),H24-G24+1,"") | J24: 23 Oct (0031_saved_lists.sql): saved items kept in the customer account (customer_lists) and on every device; merged at sign-in, cleared from the device at sign-out
A25: 2 | B25: Customer Shopping | C25: 2.6 | D25: Cart | E25: Add, update, remove items; cart saved to account | F25: Done | G25: 46317 | H25: 46318 | I25: =IF(AND(G25<>"",H25<>""),H25-G25+1,"") | J25: 23 Oct (0031_saved_lists.sql): cart kept in the customer account and on every device (sync.js); prices/stock still checked live and by place_order
A26: 2 | B26: Customer Shopping | C26: 2.7 | D26: Buyer–seller messages | E26: Buyers message sellers about a product; both reply on the Messages page | F26: Done | G26: 46317 | H26: 46317 | I26: =IF(AND(G26<>"",H26<>""),H26-G26+1,"") | J26: Built 22 Oct (messages.html, contact_messages.sql). Only buyer and seller can read a chat. 23 Oct: email alert for new messages (max one per chat every 30 minutes)
A27: 2 | B27: Customer Shopping | C27: 2.8 | D27: English / Bangla | E27: Language switch; shop pages, names of categories, products and shops in Bangla | F27: In progress | G27: 46317 | I27: =IF(AND(G27<>"",H27<>""),H27-G27+1,"") | J27: 23 Oct: i18n.js translates shopper pages (home, categories, browse, product, cart, checkout, orders, messages, alerts, sign-in, sell) with Bangla digits; Bangla name fields for categories, products, shops, home sections (0022_bangla.sql). Seller Center and Admin still English
A28: 3 | B28: Checkout & Payments | C28: 3.1 | D28: Address book | E28: Customers save delivery addresses (division, district, area) | F28: Done | G28: 46318 | H28: 46318 | I28: =IF(AND(G28<>"",H28<>""),H28-G28+1,"") | J28: Checkout remembers the last address on the device and fills it from the customer profile; full address book later · 23 Oct: account.html (profile, tiles, saved addresses up to 10 with a default, recent orders, change password); checkout picks a saved address and can save a new one (0028_customer_account.sql)
A29: 3 | B29: Checkout & Payments | C29: 3.2 | D29: Checkout flow | E29: Address → delivery option → payment → review → place order | F29: In progress | G29: 46317 | I29: =IF(AND(G29<>"",H29<>""),H29-G29+1,"") | J29: 23 Oct: checkout.html, delivery details → Cash on Delivery → one order per shop (0020_orders.sql, place_order checks prices and stock)
A30: 3 | B30: Checkout & Payments | C30: 3.3 | D30: Cash on delivery | E30: COD option with order limits | F30: In progress | G30: 46317 | I30: =IF(AND(G30<>"",H30<>""),H30-G30+1,"") | J30: Cash on Delivery is the only payment; RGBKart never holds money. Order limits per day in place
A31: 3 | B31: Checkout & Payments | C31: 3.4 | D31: bKash & Nagad | E31: Mobile wallet payments | F31: Not started | I31: =IF(AND(G31<>"",H31<>""),H31-G31+1,"") | J31: Needs merchant accounts
A32: 3 | B32: Checkout & Payments | C32: 3.5 | D32: Card payments | E32: Payment gateway (e.g. SSLCommerz) for cards | F32: Not started | I32: =IF(AND(G32<>"",H32<>""),H32-G32+1,"") | J32: Needs merchant account
A33: 3 | B33: Checkout & Payments | C33: 3.6 | D33: Coupons & vouchers | E33: Shop discount codes | F33: Done | G33: 46318 | H33: 46318 | I33: =IF(AND(G33<>"",H33<>""),H33-G33+1,"") | J33: 23 Oct (0033_shop_coupons.sql): each shop makes its own codes in Seller Center → Coupons (taka or % off, cap, minimum order, dates, total and per-buyer limits, on/off); buyers apply them per shop in the cart; place_order checks again, records the use, total = items + delivery − discount; cancelled orders give the use back; shown on invoices and My orders. Zero commission: the shop gives the discount
A34: 3 | B34: Checkout & Payments | C34: 3.7 | D34: Order confirmation | E34: Email/SMS receipt after order | F34: In progress | G34: 46317 | I34: =IF(AND(G34<>"",H34<>""),H34-G34+1,"") | J34: 23 Oct: email to the customer (if they gave an email) and the shop for each order and each status change (0021_alerts.sql). Goes live once Resend is set up. SMS later
A35: 4 | B35: Orders & Delivery | C35: 4.1 | D35: Split orders by seller | E35: One cart with several shops becomes one order per seller | F35: Done | G35: 46317 | I35: =IF(AND(G35<>"",H35<>""),H35-G35+1,"") | J35: One cart with several shops becomes one order per shop (order numbers RGB-YYMMDD-XXXXX)
A36: 4 | B36: Orders & Delivery | C36: 4.2 | D36: Seller order management | E36: Sellers accept, pack, mark shipped | F36: In progress | G36: 46317 | I36: =IF(AND(G36<>"",H36<>""),H36-G36+1,"") | J36: Seller Center → Orders: confirm, pack, ship (tracking note), deliver, cancel with reason; print invoice and packing slip
A37: 4 | B37: Orders & Delivery | C37: 4.3 | D37: Courier integration | E37: Book deliveries with couriers (e.g. Pathao, Steadfast, RedX) | F37: Not started | I37: =IF(AND(G37<>"",H37<>""),H37-G37+1,"") | J37: Needs courier API accounts
A38: 4 | B38: Orders & Delivery | C38: 4.4 | D38: Order tracking | E38: Customers see order status and tracking | F38: In progress | G38: 46317 | I38: =IF(AND(G38<>"",H38<>""),H38-G38+1,"") | J38: orders.html: customers see progress steps and the shop's delivery info; call/WhatsApp the shop
A39: 4 | B39: Orders & Delivery | C39: 4.5 | D39: Cancellations | E39: Rules for customer and seller cancellations | F39: In progress | G39: 46317 | I39: =IF(AND(G39<>"",H39<>""),H39-G39+1,"") | J39: Customer cancels while new/confirmed; shop or admin cancels with a reason; stock goes back
A40: 4 | B40: Orders & Delivery | C40: 4.6 | D40: Returns & refunds | E40: Return requests, approval, refund to wallet/payment method | F40: Done | G40: 46318 | H40: 46318 | I40: =IF(AND(G40<>"",H40<>""),H40-G40+1,"") | J40: 23 Oct (0036_returns.sql): My orders → Return this item within the product's return days (saved on the order line); reason, refund or exchange, details, up to 3 private photos; shop accepts / declines / marks item received (stock back) in Seller Center → Returns; admin sees all in Admin → Returns; alerts both ways. Refund paid by the shop directly (RGBKart holds no money)
A41: 5 | B41: Money: Payouts, Promotions & Admin | C41: 5.1 | D41: Commission rules | E41: Platform commission per category or seller | F41: Not needed | I41: =IF(AND(G41<>"",H41<>""),H41-G41+1,"") | J41: Not needed (owner, 23 Oct): zero commission, and sellers collect cash on delivery themselves, so RGBKart holds no seller money. Payouts button removed from Seller Center.
...

Sheet Summary
A1: Progress by phase
A3: Phase | B3: Phase name | C3: Sub-phases | D3: Done | E3: In progress | F3: Blocked | G3: Not started | H3: % complete | I3: First start | J3: Last end
A4: 0 | B4: Foundation (accounts & admin) | C4: =COUNTIF(Plan!$A$5:$A$283,A4)-COUNTIFS(Plan!$A$5:$A$283,A4,Plan!$F$5:$F$283,"Not needed") | D4: =COUNTIFS(Plan!$A$5:$A$283,$A4,Plan!$F$5:$F$283,"Done") | E4: =COUNTIFS(Plan!$A$5:$A$283,$A4,Plan!$F$5:$F$283,"In progress") | F4: =COUNTIFS(Plan!$A$5:$A$283,$A4,Plan!$F$5:$F$283,"Blocked") | G4: =C4-D4-E4-F4 | H4: =IF(C4=0,0,D4/C4) | I4: =IF(_xlfn.MINIFS(Plan!$G$5:$G$283,Plan!$A$5:$A$283,A4)=0,"",_xlfn.MINIFS(Plan!$G$5:$G$283,Plan!$A$5:$A$283,A4)) | J4: =IF(_xlfn.MAXIFS(Plan!$H$5:$H$283,Plan!$A$5:$A$283,A4)=0,"",_xlfn.MAXIFS(Plan!$H$5:$H$283,Plan!$A$5:$A$283,A4))
A5: 1 | B5: Catalog & Seller Products | C5: =COUNTIF(Plan!$A$5:$A$283,A5)-COUNTIFS(Plan!$A$5:$A$283,A5,Plan!$F$5:$F$283,"Not needed") | D5: =COUNTIFS(Plan!$A$5:$A$283,$A5,Plan!$F$5:$F$283,"Done") | E5: =COUNTIFS(Plan!$A$5:$A$283,$A5,Plan!$F$5:$F$283,"In progress") | F5: =COUNTIFS(Plan!$A$5:$A$283,$A5,Plan!$F$5:$F$283,"Blocked") | G5: =C5-D5-E5-F5 | H5: =IF(C5=0,0,D5/C5) | I5: =IF(_xlfn.MINIFS(Plan!$G$5:$G$283,Plan!$A$5:$A$283,A5)=0,"",_xlfn.MINIFS(Plan!$G$5:$G$283,Plan!$A$5:$A$283,A5)) | J5: =IF(_xlfn.MAXIFS(Plan!$H$5:$H$283,Plan!$A$5:$A$283,A5)=0,"",_xlfn.MAXIFS(Plan!$H$5:$H$283,Plan!$A$5:$A$283,A5))
A6: 2 | B6: Customer Shopping | C6: =COUNTIF(Plan!$A$5:$A$283,A6)-COUNTIFS(Plan!$A$5:$A$283,A6,Plan!$F$5:$F$283,"Not needed") | D6: =COUNTIFS(Plan!$A$5:$A$283,$A6,Plan!$F$5:$F$283,"Done") | E6: =COUNTIFS(Plan!$A$5:$A$283,$A6,Plan!$F$5:$F$283,"In progress") | F6: =COUNTIFS(Plan!$A$5:$A$283,$A6,Plan!$F$5:$F$283,"Blocked") | G6: =C6-D6-E6-F6 | H6: =IF(C6=0,0,D6/C6) | I6: =IF(_xlfn.MINIFS(Plan!$G$5:$G$283,Plan!$A$5:$A$283,A6)=0,"",_xlfn.MINIFS(Plan!$G$5:$G$283,Plan!$A$5:$A$283,A6)) | J6: =IF(_xlfn.MAXIFS(Plan!$H$5:$H$283,Plan!$A$5:$A$283,A6)=0,"",_xlfn.MAXIFS(Plan!$H$5:$H$283,Plan!$A$5:$A$283,A6))
A7: 3 | B7: Checkout & Payments | C7: =COUNTIF(Plan!$A$5:$A$283,A7)-COUNTIFS(Plan!$A$5:$A$283,A7,Plan!$F$5:$F$283,"Not needed") | D7: =COUNTIFS(Plan!$A$5:$A$283,$A7,Plan!$F$5:$F$283,"Done") | E7: =COUNTIFS(Plan!$A$5:$A$283,$A7,Plan!$F$5:$F$283,"In progress") | F7: =COUNTIFS(Plan!$A$5:$A$283,$A7,Plan!$F$5:$F$283,"Blocked") | G7: =C7-D7-E7-F7 | H7: =IF(C7=0,0,D7/C7) | I7: =IF(_xlfn.MINIFS(Plan!$G$5:$G$283,Plan!$A$5:$A$283,A7)=0,"",_xlfn.MINIFS(Plan!$G$5:$G$283,Plan!$A$5:$A$283,A7)) | J7: =IF(_xlfn.MAXIFS(Plan!$H$5:$H$283,Plan!$A$5:$A$283,A7)=0,"",_xlfn.MAXIFS(Plan!$H$5:$H$283,Plan!$A$5:$A$283,A7))
A8: 4 | B8: Orders & Delivery | C8: =COUNTIF(Plan!$A$5:$A$283,A8)-COUNTIFS(Plan!$A$5:$A$283,A8,Plan!$F$5:$F$283,"Not needed") | D8: =COUNTIFS(Plan!$A$5:$A$283,$A8,Plan!$F$5:$F$283,"Done") | E8: =COUNTIFS(Plan!$A$5:$A$283,$A8,Plan!$F$5:$F$283,"In progress") | F8: =COUNTIFS(Plan!$A$5:$A$283,$A8,Plan!$F$5:$F$283,"Blocked") | G8: =C8-D8-E8-F8 | H8: =IF(C8=0,0,D8/C8) | I8: =IF(_xlfn.MINIFS(Plan!$G$5:$G$283,Plan!$A$5:$A$283,A8)=0,"",_xlfn.MINIFS(Plan!$G$5:$G$283,Plan!$A$5:$A$283,A8)) | J8: =IF(_xlfn.MAXIFS(Plan!$H$5:$H$283,Plan!$A$5:$A$283,A8)=0,"",_xlfn.MAXIFS(Plan!$H$5:$H$283,Plan!$A$5:$A$283,A8))
A9: 5 | B9: Money: Payouts, Promotions & Admin | C9: =COUNTIF(Plan!$A$5:$A$283,A9)-COUNTIFS(Plan!$A$5:$A$283,A9,Plan!$F$5:$F$283,"Not needed") | D9: =COUNTIFS(Plan!$A$5:$A$283,$A9,Plan!$F$5:$F$283,"Done") | E9: =COUNTIFS(Plan!$A$5:$A$283,$A9,Plan!$F$5:$F$283,"In progress") | F9: =COUNTIFS(Plan!$A$5:$A$283,$A9,Plan!$F$5:$F$283,"Blocked") | G9: =C9-D9-E9-F9 | H9: =IF(C9=0,0,D9/C9) | I9: =IF(_xlfn.MINIFS(Plan!$G$5:$G$283,Plan!$A$5:$A$283,A9)=0,"",_xlfn.MINIFS(Plan!$G$5:$G$283,Plan!$A$5:$A$283,A9)) | J9: =IF(_xlfn.MAXIFS(Plan!$H$5:$H$283,Plan!$A$5:$A$283,A9)=0,"",_xlfn.MAXIFS(Plan!$H$5:$H$283,Plan!$A$5:$A$283,A9))
A10: 6 | B10: Reviews, Notifications & Trust | C10: =COUNTIF(Plan!$A$5:$A$283,A10)-COUNTIFS(Plan!$A$5:$A$283,A10,Plan!$F$5:$F$283,"Not needed") | D10: =COUNTIFS(Plan!$A$5:$A$283,$A10,Plan!$F$5:$F$283,"Done") | E10: =COUNTIFS(Plan!$A$5:$A$283,$A10,Plan!$F$5:$F$283,"In progress") | F10: =COUNTIFS(Plan!$A$5:$A$283,$A10,Plan!$F$5:$F$283,"Blocked") | G10: =C10-D10-E10-F10 | H10: =IF(C10=0,0,D10/C10) | I10: =IF(_xlfn.MINIFS(Plan!$G$5:$G$283,Plan!$A$5:$A$283,A10)=0,"",_xlfn.MINIFS(Plan!$G$5:$G$283,Plan!$A$5:$A$283,A10)) | J10: =IF(_xlfn.MAXIFS(Plan!$H$5:$H$283,Plan!$A$5:$A$283,A10)=0,"",_xlfn.MAXIFS(Plan!$H$5:$H$283,Plan!$A$5:$A$283,A10))
A11: 7 | B11: Launch | C11: =COUNTIF(Plan!$A$5:$A$283,A11)-COUNTIFS(Plan!$A$5:$A$283,A11,Plan!$F$5:$F$283,"Not needed") | D11: =COUNTIFS(Plan!$A$5:$A$283,$A11,Plan!$F$5:$F$283,"Done") | E11: =COUNTIFS(Plan!$A$5:$A$283,$A11,Plan!$F$5:$F$283,"In progress") | F11: =COUNTIFS(Plan!$A$5:$A$283,$A11,Plan!$F$5:$F$283,"Blocked") | G11: =C11-D11-E11-F11 | H11: =IF(C11=0,0,D11/C11) | I11: =IF(_xlfn.MINIFS(Plan!$G$5:$G$283,Plan!$A$5:$A$283,A11)=0,"",_xlfn.MINIFS(Plan!$G$5:$G$283,Plan!$A$5:$A$283,A11)) | J11: =IF(_xlfn.MAXIFS(Plan!$H$5:$H$283,Plan!$A$5:$A$283,A11)=0,"",_xlfn.MAXIFS(Plan!$H$5:$H$283,Plan!$A$5:$A$283,A11))
A12: 8 | B12: Extra work (added on owner's request) | C12: =COUNTIF(Plan!$A$5:$A$283,A12)-COUNTIFS(Plan!$A$5:$A$283,A12,Plan!$F$5:$F$283,"Not needed") | D12: =COUNTIFS(Plan!$A$5:$A$283,$A12,Plan!$F$5:$F$283,"Done") | E12: =COUNTIFS(Plan!$A$5:$A$283,$A12,Plan!$F$5:$F$283,"In progress") | F12: =COUNTIFS(Plan!$A$5:$A$283,$A12,Plan!$F$5:$F$283,"Blocked") | G12: =C12-D12-E12-F12 | H12: =IF(C12=0,0,D12/C12) | I12: =IF(_xlfn.MINIFS(Plan!$G$5:$G$283,Plan!$A$5:$A$283,A12)=0,"",_xlfn.MINIFS(Plan!$G$5:$G$283,Plan!$A$5:$A$283,A12)) | J12: =IF(_xlfn.MAXIFS(Plan!$H$5:$H$283,Plan!$A$5:$A$283,A12)=0,"",_xlfn.MAXIFS(Plan!$H$5:$H$283,Plan!$A$5:$A$283,A12))
B13: All phases | C13: =SUM(C4:C12) | D13: =SUM(D4:D12) | E13: =SUM(E4:E12) | F13: =SUM(F4:F12) | G13: =SUM(G4:G12) | H13: =IF(C13=0,0,D13/C13)
A15: Counts and dates come from the Plan tab. Status values: Not started, In progress, Blocked, Done, Not needed (left out of the counts).
